Workbook
Name تنظیمات!$C$5: تنظیمات!$C$5
Name WorkDaysPerWeek: تنظیمات!$C$6

Sheet تنظیمات
B2: تنظیمات پروژه — قابل ویرایش
B4: پارامتر | C4: مقدار | D4: توضیح
B5: تاریخ شروع پروژه | C5: 46204 | D5: تاریخ شروع فاز ۱ (قابل تغییر)
B6: روزهای کاری در هفته | C6: 6 | D6: شنبه تا چهارشنبه (قابل تغییر)
B7: فاز ۱ — مدت (روز) | C7: 90 | D7: هسته + استاندارد سازمانی + استاندارد آکادمیک
B8: فاز ۲ — مدت (روز) | C8: 90 | D8: هوشمند سازمانی + تست + آفتا
B9: دوره تست و دیباگ (روز) | C9: 60 | D9: پس از تحویل فاز ۲
B12: نکته:
B13: با تغییر مقادیر این شیت، گانت چارت به‌صورت خودکار به‌روزرسانی می‌شود.
B14: مدت هر تسک در شیت «گانت چارت» قابل ویرایش است و تاریخ‌ها خودکار محاسبه می‌شوند.

Sheet گانت چارت
B2: گانت چارت پروژه LMS مگفا — دو فازی (داینامیک)
J3: فاز ۱: هسته + استاندارد | Y3: فاز ۲: هوشمند + تست + آفتا
J4: ماه ۱ | N4: ماه ۲ | R4: ماه ۳ | V4: ماه ۴ | Z4: ماه ۵ | AD4: ماه ۶ | AH4: ماه ۷ | AL4: ماه ۸
B5: کد | C5: نام تسک | D5: فاز | E5: لایه | F5: مدت (روز) | G5: تاریخ شروع | H5: تاریخ پایان | I5: وابستگی | J5: H1 | K5: H2 | L5: H3 | M5: H4 | N5: H5 | O5: H6 | P5: H7 | Q5: H8 | R5: H9 | S5: H10 | T5: H11 | U5: H12 | V5: H13 | W5: H14 | X5: H15 | Y5: H16 | Z5: H17 | AA5: H18 | AB5: H19 | AC5: H20 | AD5: H21 | AE5: H22 | AF5: H23 | AG5: H24 | AH5: H25 | AI5: H26 | AJ5: H27 | AK5: H28 | AL5: H29 | AM5: H30 | AN5: H31 | AO5: H32
B6: P1-01 | C6: تحلیل و طراحی معماری | D6: فاز ۱ | E6: هسته | F6: 15 | G6: =تنظیمات!$C$5 | H6: =G6+F6
B7: P1-02 | C7: مدیریت هویت و دسترسی (Auth) | D7: فاز ۱ | E7: هسته | F7: 20 | G7: =MAX(H6) | H7: =G7+F7 | I7: P1-01
B8: P1-03 | C8: ساختار محتوا و دوره (Course Entity) | D8: فاز ۱ | E8: هسته | F8: 20 | G8: =MAX(H6) | H8: =G8+F8 | I8: P1-01
B9: P1-04 | C9: زیرساخت ایونت (Event Bus) | D9: فاز ۱ | E9: هسته | F9: 15 | G9: =MAX(H6) | H9: =G9+F9 | I9: P1-01
B10: P1-05 | C10: تنظیمات و هسته مرکزی (Plugin Loader) | D10: فاز ۱ | E10: هسته | F10: 15 | G10: =MAX(H6) | H10: =G10+F10 | I10: P1-01
B11: P1-06 | C11: موتور محتوا (Content Delivery) | D11: فاز ۱ | E11: هسته | F11: 20 | G11: =MAX(H8) | H11: =G11+F11 | I11: P1-03
B12: P1-07 | C12: سیستم ارزیابی (Assessment) | D12: فاز ۱ | E12: هسته | F12: 20 | G12: =MAX(H8) | H12: =G12+F12 | I12: P1-03
B13: P1-08 | C13: صدور گواهی (Certification) | D13: فاز ۱ | E13: هسته | F13: 15 | G13: =MAX(H8) | H13: =G13+F13 | I13: P1-03
B14: P1-09 | C14: داشبورد تعاملی | D14: فاز ۱ | E14: هسته | F14: 15 | G14: =MAX(H7) | H14: =G14+F14 | I14: P1-02
B15: P1-10 | C15: ساختار سازمانی (Hierarchy + RBAC) | D15: فاز ۱ | E15: سازمانی استاندارد | F15: 20 | G15: =MAX(H7) | H15: =G15+F15 | I15: P1-02
B16: P1-11 | C16: مسیر یادگیری و شایستگی | D16: فاز ۱ | E16: سازمانی استاندارد | F16: 20 | G16: =MAX(H15) | H16: =G16+F16 | I16: P1-10
B17: P1-12 | C17: گزارش‌دهی و هوش تجاری (BI) | D17: فاز ۱ | E17: سازمانی استاندارد | F17: 20 | G17: =MAX(H15) | H17: =G17+F17 | I17: P1-10
B18: P1-13 | C18: یکپارچگی HRIS | D18: فاز ۱ | E18: سازمانی استاندارد | F18: 20 | G18: =MAX(H15) | H18: =G18+F18 | I18: P1-10
B19: P1-14 | C19: ساختار ترمیک و تقویم آموزشی | D19: فاز ۱ | E19: آکادمیک استاندارد | F19: 20 | G19: =MAX(H7) | H19: =G19+F19 | I19: P1-02
B20: P1-15 | C20: مدیریت فرایندهای درسی (Rules Engine) | D20: فاز ۱ | E20: آکادمیک استاندارد | F20: 20 | G20: =MAX(H19) | H20: =G20+F20 | I20: P1-14
B21: P1-16 | C21: ارزیابی و کارنامه | D21: فاز ۱ | E21: آکادمیک استاندارد | F21: 15 | G21: =MAX(H19) | H21: =G21+F21 | I21: P1-14
B22: P1-17 | C22: یکپارچگی SIS (گلستان/سجاد) | D22: فاز ۱ | E22: آکادمیک استاندارد | F22: 25 | G22: =MAX(H19) | H22: =G22+F22 | I22: P1-14
B23: M1 | C23: تحویل فاز ۱ — MVP | D23: فاز ۱ | E23: مایل‌ستون | F23: 0 | G23: =MAX(H22) | H23: =G23 | I23: P1-17
B24: P2-01 | C24: موتور امتیازدهی (Point Engine) | D24: فاز ۲ | E24: گیمیفیکیشن | F24: 15 | G24: =MAX(H23) | H24: =G24+F24 | I24: M1
B25: P2-02 | C25: سیستم نشان و دستاورد (Badge) | D25: فاز ۲ | E25: گیمیفیکیشن | F25: 15 | G25: =MAX(H24) | H25: =G25+F25 | I25: P2-01
B26: P2-03 | C26: سطح‌بندی و لیدربورد | D26: فاز ۲ | E26: گیمیفیکیشن | F26: 15 | G26: =MAX(H24) | H26: =G26+F26 | I26: P2-01
B27: P2-04 | C27: قوانین پاداش و شخصی‌سازی | D27: فاز ۲ | E27: گیمیفیکیشن | F27: 15 | G27: =MAX(H24) | H27: =G27+F27 | I27: P2-01
B28: P2-05 | C28: داشبورد و اعلان‌های هوشمند | D28: فاز ۲ | E28: گیمیفیکیشن | F28: 15 | G28: =MAX(H26) | H28: =G28+F28 | I28: P2-03
B29: P2-06 | C29: ضدتقلب و کنترل سوءاستفاده | D29: فاز ۲ | E29: گیمیفیکیشن | F29: 10 | G29: =MAX(H24) | H29: =G29+F29 | I29: P2-01
B30: P2-07 | C30: موتور پیشنهاددهی (Recommender) | D30: فاز ۲ | E30: هوش مصنوعی | F30: 20 | G30: =MAX(H23) | H30: =G30+F30 | I30: M1
B31: P2-08 | C31: تحلیل شکاف مهارتی (Skill-Gap) | D31: فاز ۲ | E31: هوش مصنوعی | F31: 15 | G31: =MAX(H30) | H31: =G31+F31 | I31: P2-07
B32: P2-09 | C32: پشتیبانی هوشمند (AI Tutor/Chatbot) | D32: فاز ۲ | E32: هوش مصنوعی | F32: 25 | G32: =MAX(H23) | H32: =G32+F32 | I32: M1
B33: P2-10 | C33: تشخیص تقلب (Proctoring) | D33: فاز ۲ | E33: هوش مصنوعی | F33: 20 | G33: =MAX(H23) | H33: =G33+F33 | I33: M1
B34: P2-11 | C34: داشبورد پیش‌بینی (Predictive) | D34: فاز ۲ | E34: هوش مصنوعی | F34: 15 | G34: =MAX(H30) | H34: =G34+F34 | I34: P2-07
B35: P2-12 | C35: مدیریت کمیسیون و تسویه حساب | D35: فاز ۲ | E35: بازار فروش | F35: 15 | G35: =MAX(H23) | H35: =G35+F35 | I35: M1
B36: P2-13 | C36: گزارشات فروش و کوپن تخفیف | D36: فاز ۲ | E36: بازار فروش | F36: 15 | G36: =MAX(H35) | H36: =G36+F36 | I36: P2-12
B37: P2-14 | C37: امتیازدهی، سبد خرید و پرداخت | D37: فاز ۲ | E37: بازار فروش | F37: 20 | G37: =MAX(H35) | H37: =G37+F37 | I37: P2-12
B38: P2-15 | C38: جلسات Live و ابزارهای پشتیبانی | D38: فاز ۲ | E38: بازار فروش | F38: 15 | G38: =MAX(H35) | H38: =G38+F38 | I38: P2-12
B39: P2-16 | C39: تست یکپارچگی (Integration Testing) | D39: فاز ۲ | E39: تست و استقرار | F39: 20 | G39: =MAX(H38,H34,H29) | H39: =G39+F39 | I39: P2-15,P2-11,P2-06
B40: P2-17 | C40: تست کاربر (UAT) و رفع اشکال | D40: فاز ۲ | E40: تست و استقرار | F40: 20 | G40: =MAX(H39) | H40: =G40+F40 | I40: P2-16
B41: P2-18 | C41: استقرار و راه‌اندازی نهایی | D41: فاز ۲ | E41: تست و استقرار | F41: 10 | G41: =MAX(H40) | H41: =G41+F41 | I41: P2-17
...

Sheet خلاصه
B2: خلاصه زمان‌بندی پروژه
B4: شاخص | C4: مقدار | D4: توضیح
B5: تاریخ شروع پروژه | C5: =تنظیمات!$C$5 | D5: شروع فاز ۱
B6: تاریخ تحویل MVP (فاز ۱) | C6: ='گانت چارت'!G23 | D6: پایان فاز ۱ — تحویل نسخه استاندارد
B7: تاریخ تحویل نهایی (فاز ۲) | C7: ='گانت چارت'!G44 | D7: پایان فاز ۲ — تحویل نسخه هوشمند
B8: مدت فاز ۱ (روز) | C8: ='گانت چارت'!G23-تنظیمات!$C$5 | D8: از شروع تا MVP
B9: مدت فاز ۲ (روز) | C9: ='گانت چارت'!G44-'گانت چارت'!G23 | D9: از MVP تا تحویل نهایی
B10: مدت کل پروژه (روز) | C10: ='گانت چارت'!G44-تنظیمات!$C$5 | D10: از شروع تا پایان
B11: تعداد تسک‌های فاز ۱ | C11: =COUNTIF('گانت چارت'!D6:D44,"فاز ۱") | D11: هسته + استاندارد
B12: تعداد تسک‌های فاز ۲ | C12: =COUNTIF('گانت چارت'!D6:D44,"فاز ۲") | D12: هوشمند + تست + آفتا
B13: تعداد کل تسک‌ها | C13: 39 | D13: شامل مایل‌ستون‌ها
